
9
	README.md,8\e\8ec9a00bfd09b3190ac6b22251dbb1aa95a0579d
Y
)customer_exceptions/connection_problem.py,c\0\c04c5173fd4016733d791b6a90dba37389535dff
V
&customer_exceptions/nothing_deleted.py,d\8\d8e5374d0c72926139113ddb6ab00435f1855b0b
M
customer_exceptions/bad_id.py,b\0\b024104583616b220ad5bad3d723af6cda82a014
s
Ctests/service_layer/customer_service_tests/test_customer_service.py,1\9\191c7d616d48130b90131999e82c509d1e4dd2f1
h
8data_access_layer/customer_dao/customer_dao_interface.py,b\0\b0f0cfd3c0dbb48fd7e3d14c8994e04ca06e5432
J
entities/customer_class.py,5\8\58133b789b48779bb17fccea49f46d97aeee971e
I
entities/account_class.py,f\1\f1b1e202aecfc7dd7134e6c9e0bdd49c01548e9c
W
'customer_exceptions/no_account_found.py,4\8\486ee273f92f9167ff9e4beb747493b3ee6dd173
s
Ctests/data_access_layer_tests/account_dal_tests/test_account_dao.py,1\1\111c01a85c9ec2e42fbd5d1622f5a89b527ff8f3
l
<service_layer/customer_service/customer_service_interface.py,e\2\e2d05db915f8ed6817f41487db1a92f28727edfa
f
6service_layer/customer_service/customer_service_imp.py,e\5\e55b5ca74fbf0ff847132c74141f042bd4ac9409